Workbook

Sheet Настройка робота
A1: Оценка трудозатрат на настройку алгоритма робота (человеко-часов)
A2: № | B2: Наименование | C2: Тип задачи | D2: Сложность | E2: Оценка
E3: Автоматически | F3: Уточненно
A4: 1 | B4: Проверка новых писем в ящике заявок | C4: Почта/Outlook | D4: Легкая | E4: =(IF(C4='Оценка сложности задач'!$A$2,1,0)*IF(D4='Оценка сложности задач'!$B$2,1,0)*'Оценка сложности задач'!$G$2)+(IF(C4='Оценка сложности задач'!$A$3,1,0)*IF(D4='Оценка сложности задач'!$B$3,1,0)*'Оценка сложности задач'!$G$3)+(IF(C4='Оценка сложности задач'!$A$4,1,0)*IF(D4='Оценка сложности задач'!$B$4,1,0)*'Оценка сложности задач'!$G$4)+(IF(C4='Оценка сложности задач'!$A$5,1,0)*IF(D4='Оценка сложности задач'!$B$5,1,0)*'Оценка сложности задач'!$G$5)+(IF(C4='Оценка сложности задач'!$A$6,1,0)*IF(D4='Оценка сложности задач'!$B$6,1,0)*'Оценка сложности задач'!$G$6)+(IF(C4='Оценка сложности задач'!$A$7,1,0)*IF(D4='Оценка сложности задач'!$B$7,1,0)*'Оценка сложности задач'!$G$7)+(IF(C4='Оценка сложности задач'!$A$8,1,0)*IF(D4='Оценка сложности задач'!$B$8,1,0)*'Оценка сложности задач'!$G$8)+(IF(C4='Оценка сложности задач'!$A$10,1,0)*IF(D4='Оценка сложности задач'!$B$10,1,0)*'Оценка сложности задач'!$G$10)+(IF(C4='Оценка сложности задач'!$A$9,1,0)*IF(D4='Оценка сложности задач'!$B$9,1,0)*'Оценка сложности задач'!$G$9)+ (IF(C4='Оценка сложности задач'!$A$11,1,0)*IF(D4='Оценка сложности задач'!$B$11,1,0)*'Оценка сложности задач'!$G$11) + (IF(C4='Оценка сложности задач'!$A$12,1,0)*IF(D4='Оценка сложности задач'!$B$12,1,0)*'Оценка сложности задач'!$G$12) + (IF(C4='Оценка сложности задач'!$A$13,1,0)*IF(D4='Оценка сложности задач'!$B$13,1,0)*'Оценка сложности задач'!$G$13) + (IF(C4='Оценка сложности задач'!$A$14,1,0)*IF(D4='Оценка сложности задач'!$B$14,1,0)*'Оценка сложности задач'!$G$14) + (IF(C4='Оценка сложности задач'!$A$15,1,0)*IF(D4='Оценка сложности задач'!$B$15,1,0)*'Оценка сложности задач'!$G$15) + (IF(C4='Оценка сложности задач'!$A$16,1,0)*IF(D4='Оценка сложности задач'!$B$16,1,0)*'Оценка сложности задач'!$G$16) + (IF(C4='Оценка сложности задач'!$A$17,1,0)*IF(D4='Оценка сложности задач'!$B$17,1,0)*'Оценка сложности задач'!$G$17) + (IF(C4='Оценка сложности задач'!$A$18,1,0)*IF(D4='Оценка сложности задач'!$B$18,1,0)*'Оценка сложности задач'!$G$18) + (IF(C4='Оценка сложности задач'!$A$19,1,0)*IF(D4='Оценка сложности задач'!$B$19,1,0)*'Оценка сложности задач'!$G$19)+(IF(C4='Оценка сложности задач'!$A$20,1,0)*IF(D4='Оценка сложности задач'!$B$20,1,0)*'Оценка сложности задач'!$G$20)+(IF(C4='Оценка сложности задач'!$A$21,1,0)*IF(D4='Оценка сложности задач'!$B$21,1,0)*'Оценка сложности задач'!$G$21)+(IF(C4='Оценка сложности задач'!$A$22,1,0)*IF(D4='Оценка сложности задач'!$B$22,1,0)*'Оценка сложности задач'!$G$22)+(IF(C4='Оценка сложности задач'!$A$23,1,0)*IF(D4='Оценка сложности задач'!$B$23,1,0)*'Оценка сложности задач'!$G$23)+(IF(C4='Оценка сложности задач'!$A$24,1,0)*IF(D4='Оценка сложности задач'!$B$24,1,0)*'Оценка сложности задач'!$G$24)+(IF(C4='Оценка сложности задач'!$A$25,1,0)*IF(D4='Оценка сложности задач'!$B$25,1,0)*'Оценка сложности задач'!$G$25)+(IF(C4='Оценка сложности задач'!$A$26,1,0)*IF(D4='Оценка сложности задач'!$B$26,1,0)*'Оценка сложности задач'!$G$26)+(IF(C4='Оценка сложности задач'!$A$27,1,0)*IF(D4='Оценка сложности задач'!$B$27,1,0)*'Оценка сложности задач'!$G$27)+(IF(C4='Оценка сложности задач'!$A$28,1,0)*IF(D4='Оценка сложности задач'!$B$28,1,0)*'Оценка сложности задач'!$G$28)+(IF(C4='Оценка сложности задач'!$A$29,1,0)*IF(D4='Оценка сложности задач'!$B$29,1,0)*'Оценка сложности задач'!$G$29)+(IF(C4='Оценка сложности задач'!$A$30,1,0)*IF(D4='Оценка сложности задач'!$B$30,1,0)*'Оценка сложности задач'!$G$30)+(IF(C4='Оценка сложности задач'!$A$31,1,0)*IF(D4='Оценка сложности задач'!$B$31,1,0)*'Оценка сложности задач'!$G$31)+(IF(C4='Оценка сложности задач'!$A$32,1,0)*IF(D4='Оценка сложности задач'!$B$32,1,0)*'Оценка сложности задач'!$G$32)+(IF(C4='Оценка сложности задач'!$A$33,1,0)*IF(D4='Оценка сложности задач'!$B$33,1,0)*'Оценка сложности задач'!$G$33)+(IF(C4='Оценка сложности задач'!$A$34,1,0)*IF(D4='Оценка сложности задач'!$B$34,1,0)*'Оценка сложности задач'!$G$34)+(IF(C4='Оценка сложности задач'!$A$35,1,0)*IF(D4='Оценка сложности задач'!$B$35,1,0)*'Оценка сложности задач'!$G$35)+(IF(C4='Оценка сложности задач'!$A$36,1,0)*IF(D4='Оценка сложности задач'!$B$36,1,0)*'Оценка сложности задач'!$G$36)+(IF(C4='Оценка сложности задач'!$A$37,1,0)*IF(D4='Оценка сложности задач'!$B$37,1,0)*'Оценка сложности задач'!$G$37)+(IF(C4='Оценка сложности задач'!$A$38,1,0)*IF(D4='Оценка сложности задач'!$B$38,1,0)*'Оценка сложности задач'!$G$38)+(IF(C4='Оценка сложности задач'!$A$39,1,0)*IF(D4='Оценка сложности задач'!$B$39,1,0)*'Оценка сложности задач'!$G$39)+(IF(C4='Оценка сложности задач'!$A$40,1,0)*IF(D4='Оценка сложности задач'!$B$40,1,0)*'Оценка сложности задач'!$G$40) -> 6
A5: 2 | B5: Фильтрация писем: только заявки (по адресату/теме/метке) | C5: Настройка процесса | D5: Легкая | E5: =(IF(C5='Оценка сложности задач'!$A$2,1,0)*IF(D5='Оценка сложности задач'!$B$2,1,0)*'Оценка сложности задач'!$G$2)+(IF(C5='Оценка сложности задач'!$A$3,1,0)*IF(D5='Оценка сложности задач'!$B$3,1,0)*'Оценка сложности задач'!$G$3)+(IF(C5='Оценка сложности задач'!$A$4,1,0)*IF(D5='Оценка сложности задач'!$B$4,1,0)*'Оценка сложности задач'!$G$4)+(IF(C5='Оценка сложности задач'!$A$5,1,0)*IF(D5='Оценка сложности задач'!$B$5,1,0)*'Оценка сложности задач'!$G$5)+(IF(C5='Оценка сложности задач'!$A$6,1,0)*IF(D5='Оценка сложности задач'!$B$6,1,0)*'Оценка сложности задач'!$G$6)+(IF(C5='Оценка сложности задач'!$A$7,1,0)*IF(D5='Оценка сложности задач'!$B$7,1,0)*'Оценка сложности задач'!$G$7)+(IF(C5='Оценка сложности задач'!$A$8,1,0)*IF(D5='Оценка сложности задач'!$B$8,1,0)*'Оценка сложности задач'!$G$8)+(IF(C5='Оценка сложности задач'!$A$10,1,0)*IF(D5='Оценка сложности задач'!$B$10,1,0)*'Оценка сложности задач'!$G$10)+(IF(C5='Оценка сложности задач'!$A$9,1,0)*IF(D5='Оценка сложности задач'!$B$9,1,0)*'Оценка сложности задач'!$G$9)+ (IF(C5='Оценка сложности задач'!$A$11,1,0)*IF(D5='Оценка сложности задач'!$B$11,1,0)*'Оценка сложности задач'!$G$11) + (IF(C5='Оценка сложности задач'!$A$12,1,0)*IF(D5='Оценка сложности задач'!$B$12,1,0)*'Оценка сложности задач'!$G$12) + (IF(C5='Оценка сложности задач'!$A$13,1,0)*IF(D5='Оценка сложности задач'!$B$13,1,0)*'Оценка сложности задач'!$G$13) + (IF(C5='Оценка сложности задач'!$A$14,1,0)*IF(D5='Оценка сложности задач'!$B$14,1,0)*'Оценка сложности задач'!$G$14) + (IF(C5='Оценка сложности задач'!$A$15,1,0)*IF(D5='Оценка сложности задач'!$B$15,1,0)*'Оценка сложности задач'!$G$15) + (IF(C5='Оценка сложности задач'!$A$16,1,0)*IF(D5='Оценка сложности задач'!$B$16,1,0)*'Оценка сложности задач'!$G$16) + (IF(C5='Оценка сложности задач'!$A$17,1,0)*IF(D5='Оценка сложности задач'!$B$17,1,0)*'Оценка сложности задач'!$G$17) + (IF(C5='Оценка сложности задач'!$A$18,1,0)*IF(D5='Оценка сложности задач'!$B$18,1,0)*'Оценка сложности задач'!$G$18) + (IF(C5='Оценка сложности задач'!$A$19,1,0)*IF(D5='Оценка сложности задач'!$B$19,1,0)*'Оценка сложности задач'!$G$19)+(IF(C5='Оценка сложности задач'!$A$20,1,0)*IF(D5='Оценка сложности задач'!$B$20,1,0)*'Оценка сложности задач'!$G$20)+(IF(C5='Оценка сложности задач'!$A$21,1,0)*IF(D5='Оценка сложности задач'!$B$21,1,0)*'Оценка сложности задач'!$G$21)+(IF(C5='Оценка сложности задач'!$A$22,1,0)*IF(D5='Оценка сложности задач'!$B$22,1,0)*'Оценка сложности задач'!$G$22)+(IF(C5='Оценка сложности задач'!$A$23,1,0)*IF(D5='Оценка сложности задач'!$B$23,1,0)*'Оценка сложности задач'!$G$23)+(IF(C5='Оценка сложности задач'!$A$24,1,0)*IF(D5='Оценка сложности задач'!$B$24,1,0)*'Оценка сложности задач'!$G$24)+(IF(C5='Оценка сложности задач'!$A$25,1,0)*IF(D5='Оценка сложности задач'!$B$25,1,0)*'Оценка сложности задач'!$G$25)+(IF(C5='Оценка сложности задач'!$A$26,1,0)*IF(D5='Оценка сложности задач'!$B$26,1,0)*'Оценка сложности задач'!$G$26)+(IF(C5='Оценка сложности задач'!$A$27,1,0)*IF(D5='Оценка сложности задач'!$B$27,1,0)*'Оценка сложности задач'!$G$27)+(IF(C5='Оценка сложности задач'!$A$28,1,0)*IF(D5='Оценка сложности задач'!$B$28,1,0)*'Оценка сложности задач'!$G$28)+(IF(C5='Оценка сложности задач'!$A$29,1,0)*IF(D5='Оценка сложности задач'!$B$29,1,0)*'Оценка сложности задач'!$G$29)+(IF(C5='Оценка сложности задач'!$A$30,1,0)*IF(D5='Оценка сложности задач'!$B$30,1,0)*'Оценка сложности задач'!$G$30)+(IF(C5='Оценка сложности задач'!$A$31,1,0)*IF(D5='Оценка сложности задач'!$B$31,1,0)*'Оценка сложности задач'!$G$31)+(IF(C5='Оценка сложности задач'!$A$32,1,0)*IF(D5='Оценка сложности задач'!$B$32,1,0)*'Оценка сложности задач'!$G$32)+(IF(C5='Оценка сложности задач'!$A$33,1,0)*IF(D5='Оценка сложности задач'!$B$33,1,0)*'Оценка сложности задач'!$G$33)+(IF(C5='Оценка сложности задач'!$A$34,1,0)*IF(D5='Оценка сложности задач'!$B$34,1,0)*'Оценка сложности задач'!$G$34)+(IF(C5='Оценка сложности задач'!$A$35,1,0)*IF(D5='Оценка сложности задач'!$B$35,1,0)*'Оценка сложности задач'!$G$35)+(IF(C5='Оценка сложности задач'!$A$36,1,0)*IF(D5='Оценка сложности задач'!$B$36,1,0)*'Оценка сложности задач'!$G$36)+(IF(C5='Оценка сложности задач'!$A$37,1,0)*IF(D5='Оценка сложности задач'!$B$37,1,0)*'Оценка сложности задач'!$G$37)+(IF(C5='Оценка сложности задач'!$A$38,1,0)*IF(D5='Оценка сложности задач'!$B$38,1,0)*'Оценка сложности задач'!$G$38)+(IF(C5='Оценка сложности задач'!$A$39,1,0)*IF(D5='Оценка сложности задач'!$B$39,1,0)*'Оценка сложности задач'!$G$39)+(IF(C5='Оценка сложности задач'!$A$40,1,0)*IF(D5='Оценка сложности задач'!$B$40,1,0)*'Оценка сложности задач'!$G$40) -> 6
A6: 3 | B6: Сохранение письма и вложений во временную папку | C6: Файлы/Папки/FTP | D6: Средняя | E6: =(IF(C6='Оценка сложности задач'!$A$2,1,0)*IF(D6='Оценка сложности задач'!$B$2,1,0)*'Оценка сложности задач'!$G$2)+(IF(C6='Оценка сложности задач'!$A$3,1,0)*IF(D6='Оценка сложности задач'!$B$3,1,0)*'Оценка сложности задач'!$G$3)+(IF(C6='Оценка сложности задач'!$A$4,1,0)*IF(D6='Оценка сложности задач'!$B$4,1,0)*'Оценка сложности задач'!$G$4)+(IF(C6='Оценка сложности задач'!$A$5,1,0)*IF(D6='Оценка сложности задач'!$B$5,1,0)*'Оценка сложности задач'!$G$5)+(IF(C6='Оценка сложности задач'!$A$6,1,0)*IF(D6='Оценка сложности задач'!$B$6,1,0)*'Оценка сложности задач'!$G$6)+(IF(C6='Оценка сложности задач'!$A$7,1,0)*IF(D6='Оценка сложности задач'!$B$7,1,0)*'Оценка сложности задач'!$G$7)+(IF(C6='Оценка сложности задач'!$A$8,1,0)*IF(D6='Оценка сложности задач'!$B$8,1,0)*'Оценка сложности задач'!$G$8)+(IF(C6='Оценка сложности задач'!$A$10,1,0)*IF(D6='Оценка сложности задач'!$B$10,1,0)*'Оценка сложности задач'!$G$10)+(IF(C6='Оценка сложности задач'!$A$9,1,0)*IF(D6='Оценка сложности задач'!$B$9,1,0)*'Оценка сложности задач'!$G$9)+ (IF(C6='Оценка сложности задач'!$A$11,1,0)*IF(D6='Оценка сложности задач'!$B$11,1,0)*'Оценка сложности задач'!$G$11) + (IF(C6='Оценка сложности задач'!$A$12,1,0)*IF(D6='Оценка сложности задач'!$B$12,1,0)*'Оценка сложности задач'!$G$12) + (IF(C6='Оценка сложности задач'!$A$13,1,0)*IF(D6='Оценка сложности задач'!$B$13,1,0)*'Оценка сложности задач'!$G$13) + (IF(C6='Оценка сложности задач'!$A$14,1,0)*IF(D6='Оценка сложности задач'!$B$14,1,0)*'Оценка сложности задач'!$G$14) + (IF(C6='Оценка сложности задач'!$A$15,1,0)*IF(D6='Оценка сложности задач'!$B$15,1,0)*'Оценка сложности задач'!$G$15) + (IF(C6='Оценка сложности задач'!$A$16,1,0)*IF(D6='Оценка сложности задач'!$B$16,1,0)*'Оценка сложности задач'!$G$16) + (IF(C6='Оценка сложности задач'!$A$17,1,0)*IF(D6='Оценка сложности задач'!$B$17,1,0)*'Оценка сложности задач'!$G$17) + (IF(C6='Оценка сложности задач'!$A$18,1,0)*IF(D6='Оценка сложности задач'!$B$18,1,0)*'Оценка сложности задач'!$G$18) + (IF(C6='Оценка сложности задач'!$A$19,1,0)*IF(D6='Оценка сложности задач'!$B$19,1,0)*'Оценка сложности задач'!$G$19)+(IF(C6='Оценка сложности задач'!$A$20,1,0)*IF(D6='Оценка сложности задач'!$B$20,1,0)*'Оценка сложности задач'!$G$20)+(IF(C6='Оценка сложности задач'!$A$21,1,0)*IF(D6='Оценка сложности задач'!$B$21,1,0)*'Оценка сложности задач'!$G$21)+(IF(C6='Оценка сложности задач'!$A$22,1,0)*IF(D6='Оценка сложности задач'!$B$22,1,0)*'Оценка сложности задач'!$G$22)+(IF(C6='Оценка сложности задач'!$A$23,1,0)*IF(D6='Оценка сложности задач'!$B$23,1,0)*'Оценка сложности задач'!$G$23)+(IF(C6='Оценка сложности задач'!$A$24,1,0)*IF(D6='Оценка сложности задач'!$B$24,1,0)*'Оценка сложности задач'!$G$24)+(IF(C6='Оценка сложности задач'!$A$25,1,0)*IF(D6='Оценка сложности задач'!$B$25,1,0)*'Оценка сложности задач'!$G$25)+(IF(C6='Оценка сложности задач'!$A$26,1,0)*IF(D6='Оценка сложности задач'!$B$26,1,0)*'Оценка сложности задач'!$G$26)+(IF(C6='Оценка сложности задач'!$A$27,1,0)*IF(D6='Оценка сложности задач'!$B$27,1,0)*'Оценка сложности задач'!$G$27)+(IF(C6='Оценка сложности задач'!$A$28,1,0)*IF(D6='Оценка сложности задач'!$B$28,1,0)*'Оценка сложности задач'!$G$28)+(IF(C6='Оценка сложности задач'!$A$29,1,0)*IF(D6='Оценка сложности задач'!$B$29,1,0)*'Оценка сложности задач'!$G$29)+(IF(C6='Оценка сложности задач'!$A$30,1,0)*IF(D6='Оценка сложности задач'!$B$30,1,0)*'Оценка сложности задач'!$G$30)+(IF(C6='Оценка сложности задач'!$A$31,1,0)*IF(D6='Оценка сложности задач'!$B$31,1,0)*'Оценка сложности задач'!$G$31)+(IF(C6='Оценка сложности задач'!$A$32,1,0)*IF(D6='Оценка сложности задач'!$B$32,1,0)*'Оценка сложности задач'!$G$32)+(IF(C6='Оценка сложности задач'!$A$33,1,0)*IF(D6='Оценка сложности задач'!$B$33,1,0)*'Оценка сложности задач'!$G$33)+(IF(C6='Оценка сложности задач'!$A$34,1,0)*IF(D6='Оценка сложности задач'!$B$34,1,0)*'Оценка сложности задач'!$G$34)+(IF(C6='Оценка сложности задач'!$A$35,1,0)*IF(D6='Оценка сложности задач'!$B$35,1,0)*'Оценка сложности задач'!$G$35)+(IF(C6='Оценка сложности задач'!$A$36,1,0)*IF(D6='Оценка сложности задач'!$B$36,1,0)*'Оценка сложности задач'!$G$36)+(IF(C6='Оценка сложности задач'!$A$37,1,0)*IF(D6='Оценка сложности задач'!$B$37,1,0)*'Оценка сложности задач'!$G$37)+(IF(C6='Оценка сложности задач'!$A$38,1,0)*IF(D6='Оценка сложности задач'!$B$38,1,0)*'Оценка сложности задач'!$G$38)+(IF(C6='Оценка сложности задач'!$A$39,1,0)*IF(D6='Оценка сложности задач'!$B$39,1,0)*'Оценка сложности задач'!$G$39)+(IF(C6='Оценка сложности задач'!$A$40,1,0)*IF(D6='Оценка сложности задач'!$B$40,1,0)*'Оценка сложности задач'!$G$40) -> 11
A7: 4 | B7: Извлечение данных из письма: тема/тело/отправитель | C7: Обработка текста | D7: Средняя | E7: =(IF(C7='Оценка сложности задач'!$A$2,1,0)*IF(D7='Оценка сложности задач'!$B$2,1,0)*'Оценка сложности задач'!$G$2)+(IF(C7='Оценка сложности задач'!$A$3,1,0)*IF(D7='Оценка сложности задач'!$B$3,1,0)*'Оценка сложности задач'!$G$3)+(IF(C7='Оценка сложности задач'!$A$4,1,0)*IF(D7='Оценка сложности задач'!$B$4,1,0)*'Оценка сложности задач'!$G$4)+(IF(C7='Оценка сложности задач'!$A$5,1,0)*IF(D7='Оценка сложности задач'!$B$5,1,0)*'Оценка сложности задач'!$G$5)+(IF(C7='Оценка сложности задач'!$A$6,1,0)*IF(D7='Оценка сложности задач'!$B$6,1,0)*'Оценка сложности задач'!$G$6)+(IF(C7='Оценка сложности задач'!$A$7,1,0)*IF(D7='Оценка сложности задач'!$B$7,1,0)*'Оценка сложности задач'!$G$7)+(IF(C7='Оценка сложности задач'!$A$8,1,0)*IF(D7='Оценка сложности задач'!$B$8,1,0)*'Оценка сложности задач'!$G$8)+(IF(C7='Оценка сложности задач'!$A$10,1,0)*IF(D7='Оценка сложности задач'!$B$10,1,0)*'Оценка сложности задач'!$G$10)+(IF(C7='Оценка сложности задач'!$A$9,1,0)*IF(D7='Оценка сложности задач'!$B$9,1,0)*'Оценка сложности задач'!$G$9)+ (IF(C7='Оценка сложности задач'!$A$11,1,0)*IF(D7='Оценка сложности задач'!$B$11,1,0)*'Оценка сложности задач'!$G$11) + (IF(C7='Оценка сложности задач'!$A$12,1,0)*IF(D7='Оценка сложности задач'!$B$12,1,0)*'Оценка сложности задач'!$G$12) + (IF(C7='Оценка сложности задач'!$A$13,1,0)*IF(D7='Оценка сложности задач'!$B$13,1,0)*'Оценка сложности задач'!$G$13) + (IF(C7='Оценка сложности задач'!$A$14,1,0)*IF(D7='Оценка сложности задач'!$B$14,1,0)*'Оценка сложности задач'!$G$14) + (IF(C7='Оценка сложности задач'!$A$15,1,0)*IF(D7='Оценка сложности задач'!$B$15,1,0)*'Оценка сложности задач'!$G$15) + (IF(C7='Оценка сложности задач'!$A$16,1,0)*IF(D7='Оценка сложности задач'!$B$16,1,0)*'Оценка сложности задач'!$G$16) + (IF(C7='Оценка сложности задач'!$A$17,1,0)*IF(D7='Оценка сложности задач'!$B$17,1,0)*'Оценка сложности задач'!$G$17) + (IF(C7='Оценка сложности задач'!$A$18,1,0)*IF(D7='Оценка сложности задач'!$B$18,1,0)*'Оценка сложности задач'!$G$18) + (IF(C7='Оценка сложности задач'!$A$19,1,0)*IF(D7='Оценка сложности задач'!$B$19,1,0)*'Оценка сложности задач'!$G$19)+(IF(C7='Оценка сложности задач'!$A$20,1,0)*IF(D7='Оценка сложности задач'!$B$20,1,0)*'Оценка сложности задач'!$G$20)+(IF(C7='Оценка сложности задач'!$A$21,1,0)*IF(D7='Оценка сложности задач'!$B$21,1,0)*'Оценка сложности задач'!$G$21)+(IF(C7='Оценка сложности задач'!$A$22,1,0)*IF(D7='Оценка сложности задач'!$B$22,1,0)*'Оценка сложности задач'!$G$22)+(IF(C7='Оценка сложности задач'!$A$23,1,0)*IF(D7='Оценка сложности задач'!$B$23,1,0)*'Оценка сложности задач'!$G$23)+(IF(C7='Оценка сложности задач'!$A$24,1,0)*IF(D7='Оценка сложности задач'!$B$24,1,0)*'Оценка сложности задач'!$G$24)+(IF(C7='Оценка сложности задач'!$A$25,1,0)*IF(D7='Оценка сложности задач'!$B$25,1,0)*'Оценка сложности задач'!$G$25)+(IF(C7='Оценка сложности задач'!$A$26,1,0)*IF(D7='Оценка сложности задач'!$B$26,1,0)*'Оценка сложности задач'!$G$26)+(IF(C7='Оценка сложности задач'!$A$27,1,0)*IF(D7='Оценка сложности задач'!$B$27,1,0)*'Оценка сложности задач'!$G$27)+(IF(C7='Оценка сложности задач'!$A$28,1,0)*IF(D7='Оценка сложности задач'!$B$28,1,0)*'Оценка сложности задач'!$G$28)+(IF(C7='Оценка сложности задач'!$A$29,1,0)*IF(D7='Оценка сложности задач'!$B$29,1,0)*'Оценка сложности задач'!$G$29)+(IF(C7='Оценка сложности задач'!$A$30,1,0)*IF(D7='Оценка сложности задач'!$B$30,1,0)*'Оценка сложности задач'!$G$30)+(IF(C7='Оценка сложности задач'!$A$31,1,0)*IF(D7='Оценка сложности задач'!$B$31,1,0)*'Оценка сложности задач'!$G$31)+(IF(C7='Оценка сложности задач'!$A$32,1,0)*IF(D7='Оценка сложности задач'!$B$32,1,0)*'Оценка сложности задач'!$G$32)+(IF(C7='Оценка сложности задач'!$A$33,1,0)*IF(D7='Оценка сложности задач'!$B$33,1,0)*'Оценка сложности задач'!$G$33)+(IF(C7='Оценка сложности задач'!$A$34,1,0)*IF(D7='Оценка сложности задач'!$B$34,1,0)*'Оценка сложности задач'!$G$34)+(IF(C7='Оценка сложности задач'!$A$35,1,0)*IF(D7='Оценка сложности задач'!$B$35,1,0)*'Оценка сложности задач'!$G$35)+(IF(C7='Оценка сложности задач'!$A$36,1,0)*IF(D7='Оценка сложности задач'!$B$36,1,0)*'Оценка сложности задач'!$G$36)+(IF(C7='Оценка сложности задач'!$A$37,1,0)*IF(D7='Оценка сложности задач'!$B$37,1,0)*'Оценка сложности задач'!$G$37)+(IF(C7='Оценка сложности задач'!$A$38,1,0)*IF(D7='Оценка сложности задач'!$B$38,1,0)*'Оценка сложности задач'!$G$38)+(IF(C7='Оценка сложности задач'!$A$39,1,0)*IF(D7='Оценка сложности задач'!$B$39,1,0)*'Оценка сложности задач'!$G$39)+(IF(C7='Оценка сложности задач'!$A$40,1,0)*IF(D7='Оценка сложности задач'!$B$40,1,0)*'Оценка сложности задач'!$G$40) -> 6
A8: 5 | B8: Парсинг контактных данных из текста (ФИО, телефон, компания) | C8: Обработка текста | D8: Средняя | E8: =(IF(C8='Оценка сложности задач'!$A$2,1,0)*IF(D8='Оценка сложности задач'!$B$2,1,0)*'Оценка сложности задач'!$G$2)+(IF(C8='Оценка сложности задач'!$A$3,1,0)*IF(D8='Оценка сложности задач'!$B$3,1,0)*'Оценка сложности задач'!$G$3)+(IF(C8='Оценка сложности задач'!$A$4,1,0)*IF(D8='Оценка сложности задач'!$B$4,1,0)*'Оценка сложности задач'!$G$4)+(IF(C8='Оценка сложности задач'!$A$5,1,0)*IF(D8='Оценка сложности задач'!$B$5,1,0)*'Оценка сложности задач'!$G$5)+(IF(C8='Оценка сложности задач'!$A$6,1,0)*IF(D8='Оценка сложности задач'!$B$6,1,0)*'Оценка сложности задач'!$G$6)+(IF(C8='Оценка сложности задач'!$A$7,1,0)*IF(D8='Оценка сложности задач'!$B$7,1,0)*'Оценка сложности задач'!$G$7)+(IF(C8='Оценка сложности задач'!$A$8,1,0)*IF(D8='Оценка сложности задач'!$B$8,1,0)*'Оценка сложности задач'!$G$8)+(IF(C8='Оценка сложности задач'!$A$10,1,0)*IF(D8='Оценка сложности задач'!$B$10,1,0)*'Оценка сложности задач'!$G$10)+(IF(C8='Оценка сложности задач'!$A$9,1,0)*IF(D8='Оценка сложности задач'!$B$9,1,0)*'Оценка сложности задач'!$G$9)+ (IF(C8='Оценка сложности задач'!$A$11,1,0)*IF(D8='Оценка сложности задач'!$B$11,1,0)*'Оценка сложности задач'!$G$11) + (IF(C8='Оценка сложности задач'!$A$12,1,0)*IF(D8='Оценка сложности задач'!$B$12,1,0)*'Оценка сложности задач'!$G$12) + (IF(C8='Оценка сложности задач'!$A$13,1,0)*IF(D8='Оценка сложности задач'!$B$13,1,0)*'Оценка сложности задач'!$G$13) + (IF(C8='Оценка сложности задач'!$A$14,1,0)*IF(D8='Оценка сложности задач'!$B$14,1,0)*'Оценка сложности задач'!$G$14) + (IF(C8='Оценка сложности задач'!$A$15,1,0)*IF(D8='Оценка сложности задач'!$B$15,1,0)*'Оценка сложности задач'!$G$15) + (IF(C8='Оценка сложности задач'!$A$16,1,0)*IF(D8='Оценка сложности задач'!$B$16,1,0)*'Оценка сложности задач'!$G$16) + (IF(C8='Оценка сложности задач'!$A$17,1,0)*IF(D8='Оценка сложности задач'!$B$17,1,0)*'Оценка сложности задач'!$G$17) + (IF(C8='Оценка сложности задач'!$A$18,1,0)*IF(D8='Оценка сложности задач'!$B$18,1,0)*'Оценка сложности задач'!$G$18) + (IF(C8='Оценка сложности задач'!$A$19,1,0)*IF(D8='Оценка сложности задач'!$B$19,1,0)*'Оценка сложности задач'!$G$19)+(IF(C8='Оценка сложности задач'!$A$20,1,0)*IF(D8='Оценка сложности задач'!$B$20,1,0)*'Оценка сложности задач'!$G$20)+(IF(C8='Оценка сложности задач'!$A$21,1,0)*IF(D8='Оценка сложности задач'!$B$21,1,0)*'Оценка сложности задач'!$G$21)+(IF(C8='Оценка сложности задач'!$A$22,1,0)*IF(D8='Оценка сложности задач'!$B$22,1,0)*'Оценка сложности задач'!$G$22)+(IF(C8='Оценка сложности задач'!$A$23,1,0)*IF(D8='Оценка сложности задач'!$B$23,1,0)*'Оценка сложности задач'!$G$23)+(IF(C8='Оценка сложности задач'!$A$24,1,0)*IF(D8='Оценка сложности задач'!$B$24,1,0)*'Оценка сложности задач'!$G$24)+(IF(C8='Оценка сложности задач'!$A$25,1,0)*IF(D8='Оценка сложности задач'!$B$25,1,0)*'Оценка сложности задач'!$G$25)+(IF(C8='Оценка сложности задач'!$A$26,1,0)*IF(D8='Оценка сложности задач'!$B$26,1,0)*'Оценка сложности задач'!$G$26)+(IF(C8='Оценка сложности задач'!$A$27,1,0)*IF(D8='Оценка сложности задач'!$B$27,1,0)*'Оценка сложности задач'!$G$27)+(IF(C8='Оценка сложности задач'!$A$28,1,0)*IF(D8='Оценка сложности задач'!$B$28,1,0)*'Оценка сложности задач'!$G$28)+(IF(C8='Оценка сложности задач'!$A$29,1,0)*IF(D8='Оценка сложности задач'!$B$29,1,0)*'Оценка сложности задач'!$G$29)+(IF(C8='Оценка сложности задач'!$A$30,1,0)*IF(D8='Оценка сложности задач'!$B$30,1,0)*'Оценка сложности задач'!$G$30)+(IF(C8='Оценка сложности задач'!$A$31,1,0)*IF(D8='Оценка сложности задач'!$B$31,1,0)*'Оценка сложности задач'!$G$31)+(IF(C8='Оценка сложности задач'!$A$32,1,0)*IF(D8='Оценка сложности задач'!$B$32,1,0)*'Оценка сложности задач'!$G$32)+(IF(C8='Оценка сложности задач'!$A$33,1,0)*IF(D8='Оценка сложности задач'!$B$33,1,0)*'Оценка сложности задач'!$G$33)+(IF(C8='Оценка сложности задач'!$A$34,1,0)*IF(D8='Оценка сложности задач'!$B$34,1,0)*'Оценка сложности задач'!$G$34)+(IF(C8='Оценка сложности задач'!$A$35,1,0)*IF(D8='Оценка сложности задач'!$B$35,1,0)*'Оценка сложности задач'!$G$35)+(IF(C8='Оценка сложности задач'!$A$36,1,0)*IF(D8='Оценка сложности задач'!$B$36,1,0)*'Оценка сложности задач'!$G$36)+(IF(C8='Оценка сложности задач'!$A$37,1,0)*IF(D8='Оценка сложности задач'!$B$37,1,0)*'Оценка сложности задач'!$G$37)+(IF(C8='Оценка сложности задач'!$A$38,1,0)*IF(D8='Оценка сложности задач'!$B$38,1,0)*'Оценка сложности задач'!$G$38)+(IF(C8='Оценка сложности задач'!$A$39,1,0)*IF(D8='Оценка сложности задач'!$B$39,1,0)*'Оценка сложности задач'!$G$39)+(IF(C8='Оценка сложности задач'!$A$40,1,0)*IF(D8='Оценка сложности задач'!$B$40,1,0)*'Оценка сложности задач'!$G$40) -> 6
A9: 6 | B9: Проверка на дубликаты заявки (Message-ID/тема/отправитель) | C9: Базы данных | D9: Средняя | E9: =(IF(C9='Оценка сложности задач'!$A$2,1,0)*IF(D9='Оценка сложности задач'!$B$2,1,0)*'Оценка сложности задач'!$G$2)+(IF(C9='Оценка сложности задач'!$A$3,1,0)*IF(D9='Оценка сложности задач'!$B$3,1,0)*'Оценка сложности задач'!$G$3)+(IF(C9='Оценка сложности задач'!$A$4,1,0)*IF(D9='Оценка сложности задач'!$B$4,1,0)*'Оценка сложности задач'!$G$4)+(IF(C9='Оценка сложности задач'!$A$5,1,0)*IF(D9='Оценка сложности задач'!$B$5,1,0)*'Оценка сложности задач'!$G$5)+(IF(C9='Оценка сложности задач'!$A$6,1,0)*IF(D9='Оценка сложности задач'!$B$6,1,0)*'Оценка сложности задач'!$G$6)+(IF(C9='Оценка сложности задач'!$A$7,1,0)*IF(D9='Оценка сложности задач'!$B$7,1,0)*'Оценка сложности задач'!$G$7)+(IF(C9='Оценка сложности задач'!$A$8,1,0)*IF(D9='Оценка сложности задач'!$B$8,1,0)*'Оценка сложности задач'!$G$8)+(IF(C9='Оценка сложности задач'!$A$10,1,0)*IF(D9='Оценка сложности задач'!$B$10,1,0)*'Оценка сложности задач'!$G$10)+(IF(C9='Оценка сложности задач'!$A$9,1,0)*IF(D9='Оценка сложности задач'!$B$9,1,0)*'Оценка сложности задач'!$G$9)+ (IF(C9='Оценка сложности задач'!$A$11,1,0)*IF(D9='Оценка сложности задач'!$B$11,1,0)*'Оценка сложности задач'!$G$11) + (IF(C9='Оценка сложности задач'!$A$12,1,0)*IF(D9='Оценка сложности задач'!$B$12,1,0)*'Оценка сложности задач'!$G$12) + (IF(C9='Оценка сложности задач'!$A$13,1,0)*IF(D9='Оценка сложности задач'!$B$13,1,0)*'Оценка сложности задач'!$G$13) + (IF(C9='Оценка сложности задач'!$A$14,1,0)*IF(D9='Оценка сложности задач'!$B$14,1,0)*'Оценка сложности задач'!$G$14) + (IF(C9='Оценка сложности задач'!$A$15,1,0)*IF(D9='Оценка сложности задач'!$B$15,1,0)*'Оценка сложности задач'!$G$15) + (IF(C9='Оценка сложности задач'!$A$16,1,0)*IF(D9='Оценка сложности задач'!$B$16,1,0)*'Оценка сложности задач'!$G$16) + (IF(C9='Оценка сложности задач'!$A$17,1,0)*IF(D9='Оценка сложности задач'!$B$17,1,0)*'Оценка сложности задач'!$G$17) + (IF(C9='Оценка сложности задач'!$A$18,1,0)*IF(D9='Оценка сложности задач'!$B$18,1,0)*'Оценка сложности задач'!$G$18) + (IF(C9='Оценка сложности задач'!$A$19,1,0)*IF(D9='Оценка сложности задач'!$B$19,1,0)*'Оценка сложности задач'!$G$19)+(IF(C9='Оценка сложности задач'!$A$20,1,0)*IF(D9='Оценка сложности задач'!$B$20,1,0)*'Оценка сложности задач'!$G$20)+(IF(C9='Оценка сложности задач'!$A$21,1,0)*IF(D9='Оценка сложности задач'!$B$21,1,0)*'Оценка сложности задач'!$G$21)+(IF(C9='Оценка сложности задач'!$A$22,1,0)*IF(D9='Оценка сложности задач'!$B$22,1,0)*'Оценка сложности задач'!$G$22)+(IF(C9='Оценка сложности задач'!$A$23,1,0)*IF(D9='Оценка сложности задач'!$B$23,1,0)*'Оценка сложности задач'!$G$23)+(IF(C9='Оценка сложности задач'!$A$24,1,0)*IF(D9='Оценка сложности задач'!$B$24,1,0)*'Оценка сложности задач'!$G$24)+(IF(C9='Оценка сложности задач'!$A$25,1,0)*IF(D9='Оценка сложности задач'!$B$25,1,0)*'Оценка сложности задач'!$G$25)+(IF(C9='Оценка сложности задач'!$A$26,1,0)*IF(D9='Оценка сложности задач'!$B$26,1,0)*'Оценка сложности задач'!$G$26)+(IF(C9='Оценка сложности задач'!$A$27,1,0)*IF(D9='Оценка сложности задач'!$B$27,1,0)*'Оценка сложности задач'!$G$27)+(IF(C9='Оценка сложности задач'!$A$28,1,0)*IF(D9='Оценка сложности задач'!$B$28,1,0)*'Оценка сложности задач'!$G$28)+(IF(C9='Оценка сложности задач'!$A$29,1,0)*IF(D9='Оценка сложности задач'!$B$29,1,0)*'Оценка сложности задач'!$G$29)+(IF(C9='Оценка сложности задач'!$A$30,1,0)*IF(D9='Оценка сложности задач'!$B$30,1,0)*'Оценка сложности задач'!$G$30)+(IF(C9='Оценка сложности задач'!$A$31,1,0)*IF(D9='Оценка сложности задач'!$B$31,1,0)*'Оценка сложности задач'!$G$31)+(IF(C9='Оценка сложности задач'!$A$32,1,0)*IF(D9='Оценка сложности задач'!$B$32,1,0)*'Оценка сложности задач'!$G$32)+(IF(C9='Оценка сложности задач'!$A$33,1,0)*IF(D9='Оценка сложности задач'!$B$33,1,0)*'Оценка сложности задач'!$G$33)+(IF(C9='Оценка сложности задач'!$A$34,1,0)*IF(D9='Оценка сложности задач'!$B$34,1,0)*'Оценка сложности задач'!$G$34)+(IF(C9='Оценка сложности задач'!$A$35,1,0)*IF(D9='Оценка сложности задач'!$B$35,1,0)*'Оценка сложности задач'!$G$35)+(IF(C9='Оценка сложности задач'!$A$36,1,0)*IF(D9='Оценка сложности задач'!$B$36,1,0)*'Оценка сложности задач'!$G$36)+(IF(C9='Оценка сложности задач'!$A$37,1,0)*IF(D9='Оценка сложности задач'!$B$37,1,0)*'Оценка сложности задач'!$G$37)+(IF(C9='Оценка сложности задач'!$A$38,1,0)*IF(D9='Оценка сложности задач'!$B$38,1,0)*'Оценка сложности задач'!$G$38)+(IF(C9='Оценка сложности задач'!$A$39,1,0)*IF(D9='Оценка сложности задач'!$B$39,1,0)*'Оценка сложности задач'!$G$39)+(IF(C9='Оценка сложности задач'!$A$40,1,0)*IF(D9='Оценка сложности задач'!$B$40,1,0)*'Оценка сложности задач'!$G$40) -> 32
A10: 7 | B10: Создание задачи/карточки в YouGile через API | C10: REST/SOAP | D10: Средняя | E10: =(IF(C10='Оценка сложности задач'!$A$2,1,0)*IF(D10='Оценка сложности задач'!$B$2,1,0)*'Оценка сложности задач'!$G$2)+(IF(C10='Оценка сложности задач'!$A$3,1,0)*IF(D10='Оценка сложности задач'!$B$3,1,0)*'Оценка сложности задач'!$G$3)+(IF(C10='Оценка сложности задач'!$A$4,1,0)*IF(D10='Оценка сложности задач'!$B$4,1,0)*'Оценка сложности задач'!$G$4)+(IF(C10='Оценка сложности задач'!$A$5,1,0)*IF(D10='Оценка сложности задач'!$B$5,1,0)*'Оценка сложности задач'!$G$5)+(IF(C10='Оценка сложности задач'!$A$6,1,0)*IF(D10='Оценка сложности задач'!$B$6,1,0)*'Оценка сложности задач'!$G$6)+(IF(C10='Оценка сложности задач'!$A$7,1,0)*IF(D10='Оценка сложности задач'!$B$7,1,0)*'Оценка сложности задач'!$G$7)+(IF(C10='Оценка сложности задач'!$A$8,1,0)*IF(D10='Оценка сложности задач'!$B$8,1,0)*'Оценка сложности задач'!$G$8)+(IF(C10='Оценка сложности задач'!$A$10,1,0)*IF(D10='Оценка сложности задач'!$B$10,1,0)*'Оценка сложности задач'!$G$10)+(IF(C10='Оценка сложности задач'!$A$9,1,0)*IF(D10='Оценка сложности задач'!$B$9,1,0)*'Оценка сложности задач'!$G$9)+ (IF(C10='Оценка сложности задач'!$A$11,1,0)*IF(D10='Оценка сложности задач'!$B$11,1,0)*'Оценка сложности задач'!$G$11) + (IF(C10='Оценка сложности задач'!$A$12,1,0)*IF(D10='Оценка сложности задач'!$B$12,1,0)*'Оценка сложности задач'!$G$12) + (IF(C10='Оценка сложности задач'!$A$13,1,0)*IF(D10='Оценка сложности задач'!$B$13,1,0)*'Оценка сложности задач'!$G$13) + (IF(C10='Оценка сложности задач'!$A$14,1,0)*IF(D10='Оценка сложности задач'!$B$14,1,0)*'Оценка сложности задач'!$G$14) + (IF(C10='Оценка сложности задач'!$A$15,1,0)*IF(D10='Оценка сложности задач'!$B$15,1,0)*'Оценка сложности задач'!$G$15) + (IF(C10='Оценка сложности задач'!$A$16,1,0)*IF(D10='Оценка сложности задач'!$B$16,1,0)*'Оценка сложности задач'!$G$16) + (IF(C10='Оценка сложности задач'!$A$17,1,0)*IF(D10='Оценка сложности задач'!$B$17,1,0)*'Оценка сложности задач'!$G$17) + (IF(C10='Оценка сложности задач'!$A$18,1,0)*IF(D10='Оценка сложности задач'!$B$18,1,0)*'Оценка сложности задач'!$G$18) + (IF(C10='Оценка сложности задач'!$A$19,1,0)*IF(D10='Оценка сложности задач'!$B$19,1,0)*'Оценка сложности задач'!$G$19)+(IF(C10='Оценка сложности задач'!$A$20,1,0)*IF(D10='Оценка сложности задач'!$B$20,1,0)*'Оценка сложности задач'!$G$20)+(IF(C10='Оценка сложности задач'!$A$21,1,0)*IF(D10='Оценка сложности задач'!$B$21,1,0)*'Оценка сложности задач'!$G$21)+(IF(C10='Оценка сложности задач'!$A$22,1,0)*IF(D10='Оценка сложности задач'!$B$22,1,0)*'Оценка сложности задач'!$G$22)+(IF(C10='Оценка сложности задач'!$A$23,1,0)*IF(D10='Оценка сложности задач'!$B$23,1,0)*'Оценка сложности задач'!$G$23)+(IF(C10='Оценка сложности задач'!$A$24,1,0)*IF(D10='Оценка сложности задач'!$B$24,1,0)*'Оценка сложности задач'!$G$24)+(IF(C10='Оценка сложности задач'!$A$25,1,0)*IF(D10='Оценка сложности задач'!$B$25,1,0)*'Оценка сложности задач'!$G$25)+(IF(C10='Оценка сложности задач'!$A$26,1,0)*IF(D10='Оценка сложности задач'!$B$26,1,0)*'Оценка сложности задач'!$G$26)+(IF(C10='Оценка сложности задач'!$A$27,1,0)*IF(D10='Оценка сложности задач'!$B$27,1,0)*'Оценка сложности задач'!$G$27)+(IF(C10='Оценка сложности задач'!$A$28,1,0)*IF(D10='Оценка сложности задач'!$B$28,1,0)*'Оценка сложности задач'!$G$28)+(IF(C10='Оценка сложности задач'!$A$29,1,0)*IF(D10='Оценка сложности задач'!$B$29,1,0)*'Оценка сложности задач'!$G$29)+(IF(C10='Оценка сложности задач'!$A$30,1,0)*IF(D10='Оценка сложности задач'!$B$30,1,0)*'Оценка сложности задач'!$G$30)+(IF(C10='Оценка сложности задач'!$A$31,1,0)*IF(D10='Оценка сложности задач'!$B$31,1,0)*'Оценка сложности задач'!$G$31)+(IF(C10='Оценка сложности задач'!$A$32,1,0)*IF(D10='Оценка сложности задач'!$B$32,1,0)*'Оценка сложности задач'!$G$32)+(IF(C10='Оценка сложности задач'!$A$33,1,0)*IF(D10='Оценка сложности задач'!$B$33,1,0)*'Оценка сложности задач'!$G$33)+(IF(C10='Оценка сложности задач'!$A$34,1,0)*IF(D10='Оценка сложности задач'!$B$34,1,0)*'Оценка сложности задач'!$G$34)+(IF(C10='Оценка сложности задач'!$A$35,1,0)*IF(D10='Оценка сложности задач'!$B$35,1,0)*'Оценка сложности задач'!$G$35)+(IF(C10='Оценка сложности задач'!$A$36,1,0)*IF(D10='Оценка сложности задач'!$B$36,1,0)*'Оценка сложности задач'!$G$36)+(IF(C10='Оценка сложности задач'!$A$37,1,0)*IF(D10='Оценка сложности задач'!$B$37,1,0)*'Оценка сложности задач'!$G$37)+(IF(C10='Оценка сложности задач'!$A$38,1,0)*IF(D10='Оценка сложности задач'!$B$38,1,0)*'Оценка сложности задач'!$G$38)+(IF(C10='Оценка сложности задач'!$A$39,1,0)*IF(D10='Оценка сложности задач'!$B$39,1,0)*'Оценка сложности задач'!$G$39)+(IF(C10='Оценка сложности задач'!$A$40,1,0)*IF(D10='Оценка сложности задач'!$B$40,1,0)*'Оценка сложности задач'!$G$40) -> 32
A11: 8 | B11: Заполнение полей задачи: описание, контакты, теги, приоритет | C11: Интеграции | D11: Средняя | E11: =(IF(C11='Оценка сложности задач'!$A$2,1,0)*IF(D11='Оценка сложности задач'!$B$2,1,0)*'Оценка сложности задач'!$G$2)+(IF(C11='Оценка сложности задач'!$A$3,1,0)*IF(D11='Оценка сложности задач'!$B$3,1,0)*'Оценка сложности задач'!$G$3)+(IF(C11='Оценка сложности задач'!$A$4,1,0)*IF(D11='Оценка сложности задач'!$B$4,1,0)*'Оценка сложности задач'!$G$4)+(IF(C11='Оценка сложности задач'!$A$5,1,0)*IF(D11='Оценка сложности задач'!$B$5,1,0)*'Оценка сложности задач'!$G$5)+(IF(C11='Оценка сложности задач'!$A$6,1,0)*IF(D11='Оценка сложности задач'!$B$6,1,0)*'Оценка сложности задач'!$G$6)+(IF(C11='Оценка сложности задач'!$A$7,1,0)*IF(D11='Оценка сложности задач'!$B$7,1,0)*'Оценка сложности задач'!$G$7)+(IF(C11='Оценка сложности задач'!$A$8,1,0)*IF(D11='Оценка сложности задач'!$B$8,1,0)*'Оценка сложности задач'!$G$8)+(IF(C11='Оценка сложности задач'!$A$10,1,0)*IF(D11='Оценка сложности задач'!$B$10,1,0)*'Оценка сложности задач'!$G$10)+(IF(C11='Оценка сложности задач'!$A$9,1,0)*IF(D11='Оценка сложности задач'!$B$9,1,0)*'Оценка сложности задач'!$G$9)+ (IF(C11='Оценка сложности задач'!$A$11,1,0)*IF(D11='Оценка сложности задач'!$B$11,1,0)*'Оценка сложности задач'!$G$11) + (IF(C11='Оценка сложности задач'!$A$12,1,0)*IF(D11='Оценка сложности задач'!$B$12,1,0)*'Оценка сложности задач'!$G$12) + (IF(C11='Оценка сложности задач'!$A$13,1,0)*IF(D11='Оценка сложности задач'!$B$13,1,0)*'Оценка сложности задач'!$G$13) + (IF(C11='Оценка сложности задач'!$A$14,1,0)*IF(D11='Оценка сложности задач'!$B$14,1,0)*'Оценка сложности задач'!$G$14) + (IF(C11='Оценка сложности задач'!$A$15,1,0)*IF(D11='Оценка сложности задач'!$B$15,1,0)*'Оценка сложности задач'!$G$15) + (IF(C11='Оценка сложности задач'!$A$16,1,0)*IF(D11='Оценка сложности задач'!$B$16,1,0)*'Оценка сложности задач'!$G$16) + (IF(C11='Оценка сложности задач'!$A$17,1,0)*IF(D11='Оценка сложности задач'!$B$17,1,0)*'Оценка сложности задач'!$G$17) + (IF(C11='Оценка сложности задач'!$A$18,1,0)*IF(D11='Оценка сложности задач'!$B$18,1,0)*'Оценка сложности задач'!$G$18) + (IF(C11='Оценка сложности задач'!$A$19,1,0)*IF(D11='Оценка сложности задач'!$B$19,1,0)*'Оценка сложности задач'!$G$19)+(IF(C11='Оценка сложности задач'!$A$20,1,0)*IF(D11='Оценка сложности задач'!$B$20,1,0)*'Оценка сложности задач'!$G$20)+(IF(C11='Оценка сложности задач'!$A$21,1,0)*IF(D11='Оценка сложности задач'!$B$21,1,0)*'Оценка сложности задач'!$G$21)+(IF(C11='Оценка сложности задач'!$A$22,1,0)*IF(D11='Оценка сложности задач'!$B$22,1,0)*'Оценка сложности задач'!$G$22)+(IF(C11='Оценка сложности задач'!$A$23,1,0)*IF(D11='Оценка сложности задач'!$B$23,1,0)*'Оценка сложности задач'!$G$23)+(IF(C11='Оценка сложности задач'!$A$24,1,0)*IF(D11='Оценка сложности задач'!$B$24,1,0)*'Оценка сложности задач'!$G$24)+(IF(C11='Оценка сложности задач'!$A$25,1,0)*IF(D11='Оценка сложности задач'!$B$25,1,0)*'Оценка сложности задач'!$G$25)+(IF(C11='Оценка сложности задач'!$A$26,1,0)*IF(D11='Оценка сложности задач'!$B$26,1,0)*'Оценка сложности задач'!$G$26)+(IF(C11='Оценка сложности задач'!$A$27,1,0)*IF(D11='Оценка сложности задач'!$B$27,1,0)*'Оценка сложности задач'!$G$27)+(IF(C11='Оценка сложности задач'!$A$28,1,0)*IF(D11='Оценка сложности задач'!$B$28,1,0)*'Оценка сложности задач'!$G$28)+(IF(C11='Оценка сложности задач'!$A$29,1,0)*IF(D11='Оценка сложности задач'!$B$29,1,0)*'Оценка сложности задач'!$G$29)+(IF(C11='Оценка сложности задач'!$A$30,1,0)*IF(D11='Оценка сложности задач'!$B$30,1,0)*'Оценка сложности задач'!$G$30)+(IF(C11='Оценка сложности задач'!$A$31,1,0)*IF(D11='Оценка сложности задач'!$B$31,1,0)*'Оценка сложности задач'!$G$31)+(IF(C11='Оценка сложности задач'!$A$32,1,0)*IF(D11='Оценка сложности задач'!$B$32,1,0)*'Оценка сложности задач'!$G$32)+(IF(C11='Оценка сложности задач'!$A$33,1,0)*IF(D11='Оценка сложности задач'!$B$33,1,0)*'Оценка сложности задач'!$G$33)+(IF(C11='Оценка сложности задач'!$A$34,1,0)*IF(D11='Оценка сложности задач'!$B$34,1,0)*'Оценка сложности задач'!$G$34)+(IF(C11='Оценка сложности задач'!$A$35,1,0)*IF(D11='Оценка сложности задач'!$B$35,1,0)*'Оценка сложности задач'!$G$35)+(IF(C11='Оценка сложности задач'!$A$36,1,0)*IF(D11='Оценка сложности задач'!$B$36,1,0)*'Оценка сложности задач'!$G$36)+(IF(C11='Оценка сложности задач'!$A$37,1,0)*IF(D11='Оценка сложности задач'!$B$37,1,0)*'Оценка сложности задач'!$G$37)+(IF(C11='Оценка сложности задач'!$A$38,1,0)*IF(D11='Оценка сложности задач'!$B$38,1,0)*'Оценка сложности задач'!$G$38)+(IF(C11='Оценка сложности задач'!$A$39,1,0)*IF(D11='Оценка сложности задач'!$B$39,1,0)*'Оценка сложности задач'!$G$39)+(IF(C11='Оценка сложности задач'!$A$40,1,0)*IF(D11='Оценка сложности задач'!$B$40,1,0)*'Оценка сложности задач'!$G$40) -> 32
A12: 9 | B12: Прикрепление вложений к задаче (если есть) | C12: Файлы/Папки/FTP | D12: Средняя | E12: =(IF(C12='Оценка сложности задач'!$A$2,1,0)*IF(D12='Оценка сложности задач'!$B$2,1,0)*'Оценка сложности задач'!$G$2)+(IF(C12='Оценка сложности задач'!$A$3,1,0)*IF(D12='Оценка сложности задач'!$B$3,1,0)*'Оценка сложности задач'!$G$3)+(IF(C12='Оценка сложности задач'!$A$4,1,0)*IF(D12='Оценка сложности задач'!$B$4,1,0)*'Оценка сложности задач'!$G$4)+(IF(C12='Оценка сложности задач'!$A$5,1,0)*IF(D12='Оценка сложности задач'!$B$5,1,0)*'Оценка сложности задач'!$G$5)+(IF(C12='Оценка сложности задач'!$A$6,1,0)*IF(D12='Оценка сложности задач'!$B$6,1,0)*'Оценка сложности задач'!$G$6)+(IF(C12='Оценка сложности задач'!$A$7,1,0)*IF(D12='Оценка сложности задач'!$B$7,1,0)*'Оценка сложности задач'!$G$7)+(IF(C12='Оценка сложности задач'!$A$8,1,0)*IF(D12='Оценка сложности задач'!$B$8,1,0)*'Оценка сложности задач'!$G$8)+(IF(C12='Оценка сложности задач'!$A$10,1,0)*IF(D12='Оценка сложности задач'!$B$10,1,0)*'Оценка сложности задач'!$G$10)+(IF(C12='Оценка сложности задач'!$A$9,1,0)*IF(D12='Оценка сложности задач'!$B$9,1,0)*'Оценка сложности задач'!$G$9)+ (IF(C12='Оценка сложности задач'!$A$11,1,0)*IF(D12='Оценка сложности задач'!$B$11,1,0)*'Оценка сложности задач'!$G$11) + (IF(C12='Оценка сложности задач'!$A$12,1,0)*IF(D12='Оценка сложности задач'!$B$12,1,0)*'Оценка сложности задач'!$G$12) + (IF(C12='Оценка сложности задач'!$A$13,1,0)*IF(D12='Оценка сложности задач'!$B$13,1,0)*'Оценка сложности задач'!$G$13) + (IF(C12='Оценка сложности задач'!$A$14,1,0)*IF(D12='Оценка сложности задач'!$B$14,1,0)*'Оценка сложности задач'!$G$14) + (IF(C12='Оценка сложности задач'!$A$15,1,0)*IF(D12='Оценка сложности задач'!$B$15,1,0)*'Оценка сложности задач'!$G$15) + (IF(C12='Оценка сложности задач'!$A$16,1,0)*IF(D12='Оценка сложности задач'!$B$16,1,0)*'Оценка сложности задач'!$G$16) + (IF(C12='Оценка сложности задач'!$A$17,1,0)*IF(D12='Оценка сложности задач'!$B$17,1,0)*'Оценка сложности задач'!$G$17) + (IF(C12='Оценка сложности задач'!$A$18,1,0)*IF(D12='Оценка сложности задач'!$B$18,1,0)*'Оценка сложности задач'!$G$18) + (IF(C12='Оценка сложности задач'!$A$19,1,0)*IF(D12='Оценка сложности задач'!$B$19,1,0)*'Оценка сложности задач'!$G$19)+(IF(C12='Оценка сложности задач'!$A$20,1,0)*IF(D12='Оценка сложности задач'!$B$20,1,0)*'Оценка сложности задач'!$G$20)+(IF(C12='Оценка сложности задач'!$A$21,1,0)*IF(D12='Оценка сложности задач'!$B$21,1,0)*'Оценка сложности задач'!$G$21)+(IF(C12='Оценка сложности задач'!$A$22,1,0)*IF(D12='Оценка сложности задач'!$B$22,1,0)*'Оценка сложности задач'!$G$22)+(IF(C12='Оценка сложности задач'!$A$23,1,0)*IF(D12='Оценка сложности задач'!$B$23,1,0)*'Оценка сложности задач'!$G$23)+(IF(C12='Оценка сложности задач'!$A$24,1,0)*IF(D12='Оценка сложности задач'!$B$24,1,0)*'Оценка сложности задач'!$G$24)+(IF(C12='Оценка сложности задач'!$A$25,1,0)*IF(D12='Оценка сложности задач'!$B$25,1,0)*'Оценка сложности задач'!$G$25)+(IF(C12='Оценка сложности задач'!$A$26,1,0)*IF(D12='Оценка сложности задач'!$B$26,1,0)*'Оценка сложности задач'!$G$26)+(IF(C12='Оценка сложности задач'!$A$27,1,0)*IF(D12='Оценка сложности задач'!$B$27,1,0)*'Оценка сложности задач'!$G$27)+(IF(C12='Оценка сложности задач'!$A$28,1,0)*IF(D12='Оценка сложности задач'!$B$28,1,0)*'Оценка сложности задач'!$G$28)+(IF(C12='Оценка сложности задач'!$A$29,1,0)*IF(D12='Оценка сложности задач'!$B$29,1,0)*'Оценка сложности задач'!$G$29)+(IF(C12='Оценка сложности задач'!$A$30,1,0)*IF(D12='Оценка сложности задач'!$B$30,1,0)*'Оценка сложности задач'!$G$30)+(IF(C12='Оценка сложности задач'!$A$31,1,0)*IF(D12='Оценка сложности задач'!$B$31,1,0)*'Оценка сложности задач'!$G$31)+(IF(C12='Оценка сложности задач'!$A$32,1,0)*IF(D12='Оценка сложности задач'!$B$32,1,0)*'Оценка сложности задач'!$G$32)+(IF(C12='Оценка сложности задач'!$A$33,1,0)*IF(D12='Оценка сложности задач'!$B$33,1,0)*'Оценка сложности задач'!$G$33)+(IF(C12='Оценка сложности задач'!$A$34,1,0)*IF(D12='Оценка сложности задач'!$B$34,1,0)*'Оценка сложности задач'!$G$34)+(IF(C12='Оценка сложности задач'!$A$35,1,0)*IF(D12='Оценка сложности задач'!$B$35,1,0)*'Оценка сложности задач'!$G$35)+(IF(C12='Оценка сложности задач'!$A$36,1,0)*IF(D12='Оценка сложности задач'!$B$36,1,0)*'Оценка сложности задач'!$G$36)+(IF(C12='Оценка сложности задач'!$A$37,1,0)*IF(D12='Оценка сложности задач'!$B$37,1,0)*'Оценка сложности задач'!$G$37)+(IF(C12='Оценка сложности задач'!$A$38,1,0)*IF(D12='Оценка сложности задач'!$B$38,1,0)*'Оценка сложности задач'!$G$38)+(IF(C12='Оценка сложности задач'!$A$39,1,0)*IF(D12='Оценка сложности задач'!$B$39,1,0)*'Оценка сложности задач'!$G$39)+(IF(C12='Оценка сложности задач'!$A$40,1,0)*IF(D12='Оценка сложности задач'!$B$40,1,0)*'Оценка сложности задач'!$G$40) -> 11
A13: 10 | B13: Уведомление менеджера о созданной задаче | C13: Почта/Outlook | D13: Легкая | E13: =(IF(C13='Оценка сложности задач'!$A$2,1,0)*IF(D13='Оценка сложности задач'!$B$2,1,0)*'Оценка сложности задач'!$G$2)+(IF(C13='Оценка сложности задач'!$A$3,1,0)*IF(D13='Оценка сложности задач'!$B$3,1,0)*'Оценка сложности задач'!$G$3)+(IF(C13='Оценка сложности задач'!$A$4,1,0)*IF(D13='Оценка сложности задач'!$B$4,1,0)*'Оценка сложности задач'!$G$4)+(IF(C13='Оценка сложности задач'!$A$5,1,0)*IF(D13='Оценка сложности задач'!$B$5,1,0)*'Оценка сложности задач'!$G$5)+(IF(C13='Оценка сложности задач'!$A$6,1,0)*IF(D13='Оценка сложности задач'!$B$6,1,0)*'Оценка сложности задач'!$G$6)+(IF(C13='Оценка сложности задач'!$A$7,1,0)*IF(D13='Оценка сложности задач'!$B$7,1,0)*'Оценка сложности задач'!$G$7)+(IF(C13='Оценка сложности задач'!$A$8,1,0)*IF(D13='Оценка сложности задач'!$B$8,1,0)*'Оценка сложности задач'!$G$8)+(IF(C13='Оценка сложности задач'!$A$10,1,0)*IF(D13='Оценка сложности задач'!$B$10,1,0)*'Оценка сложности задач'!$G$10)+(IF(C13='Оценка сложности задач'!$A$9,1,0)*IF(D13='Оценка сложности задач'!$B$9,1,0)*'Оценка сложности задач'!$G$9)+ (IF(C13='Оценка сложности задач'!$A$11,1,0)*IF(D13='Оценка сложности задач'!$B$11,1,0)*'Оценка сложности задач'!$G$11) + (IF(C13='Оценка сложности задач'!$A$12,1,0)*IF(D13='Оценка сложности задач'!$B$12,1,0)*'Оценка сложности задач'!$G$12) + (IF(C13='Оценка сложности задач'!$A$13,1,0)*IF(D13='Оценка сложности задач'!$B$13,1,0)*'Оценка сложности задач'!$G$13) + (IF(C13='Оценка сложности задач'!$A$14,1,0)*IF(D13='Оценка сложности задач'!$B$14,1,0)*'Оценка сложности задач'!$G$14) + (IF(C13='Оценка сложности задач'!$A$15,1,0)*IF(D13='Оценка сложности задач'!$B$15,1,0)*'Оценка сложности задач'!$G$15) + (IF(C13='Оценка сложности задач'!$A$16,1,0)*IF(D13='Оценка сложности задач'!$B$16,1,0)*'Оценка сложности задач'!$G$16) + (IF(C13='Оценка сложности задач'!$A$17,1,0)*IF(D13='Оценка сложности задач'!$B$17,1,0)*'Оценка сложности задач'!$G$17) + (IF(C13='Оценка сложности задач'!$A$18,1,0)*IF(D13='Оценка сложности задач'!$B$18,1,0)*'Оценка сложности задач'!$G$18) + (IF(C13='Оценка сложности задач'!$A$19,1,0)*IF(D13='Оценка сложности задач'!$B$19,1,0)*'Оценка сложности задач'!$G$19)+(IF(C13='Оценка сложности задач'!$A$20,1,0)*IF(D13='Оценка сложности задач'!$B$20,1,0)*'Оценка сложности задач'!$G$20)+(IF(C13='Оценка сложности задач'!$A$21,1,0)*IF(D13='Оценка сложности задач'!$B$21,1,0)*'Оценка сложности задач'!$G$21)+(IF(C13='Оценка сложности задач'!$A$22,1,0)*IF(D13='Оценка сложности задач'!$B$22,1,0)*'Оценка сложности задач'!$G$22)+(IF(C13='Оценка сложности задач'!$A$23,1,0)*IF(D13='Оценка сложности задач'!$B$23,1,0)*'Оценка сложности задач'!$G$23)+(IF(C13='Оценка сложности задач'!$A$24,1,0)*IF(D13='Оценка сложности задач'!$B$24,1,0)*'Оценка сложности задач'!$G$24)+(IF(C13='Оценка сложности задач'!$A$25,1,0)*IF(D13='Оценка сложности задач'!$B$25,1,0)*'Оценка сложности задач'!$G$25)+(IF(C13='Оценка сложности задач'!$A$26,1,0)*IF(D13='Оценка сложности задач'!$B$26,1,0)*'Оценка сложности задач'!$G$26)+(IF(C13='Оценка сложности задач'!$A$27,1,0)*IF(D13='Оценка сложности задач'!$B$27,1,0)*'Оценка сложности задач'!$G$27)+(IF(C13='Оценка сложности задач'!$A$28,1,0)*IF(D13='Оценка сложности задач'!$B$28,1,0)*'Оценка сложности задач'!$G$28)+(IF(C13='Оценка сложности задач'!$A$29,1,0)*IF(D13='Оценка сложности задач'!$B$29,1,0)*'Оценка сложности задач'!$G$29)+(IF(C13='Оценка сложности задач'!$A$30,1,0)*IF(D13='Оценка сложности задач'!$B$30,1,0)*'Оценка сложности задач'!$G$30)+(IF(C13='Оценка сложности задач'!$A$31,1,0)*IF(D13='Оценка сложности задач'!$B$31,1,0)*'Оценка сложности задач'!$G$31)+(IF(C13='Оценка сложности задач'!$A$32,1,0)*IF(D13='Оценка сложности задач'!$B$32,1,0)*'Оценка сложности задач'!$G$32)+(IF(C13='Оценка сложности задач'!$A$33,1,0)*IF(D13='Оценка сложности задач'!$B$33,1,0)*'Оценка сложности задач'!$G$33)+(IF(C13='Оценка сложности задач'!$A$34,1,0)*IF(D13='Оценка сложности задач'!$B$34,1,0)*'Оценка сложности задач'!$G$34)+(IF(C13='Оценка сложности задач'!$A$35,1,0)*IF(D13='Оценка сложности задач'!$B$35,1,0)*'Оценка сложности задач'!$G$35)+(IF(C13='Оценка сложности задач'!$A$36,1,0)*IF(D13='Оценка сложности задач'!$B$36,1,0)*'Оценка сложности задач'!$G$36)+(IF(C13='Оценка сложности задач'!$A$37,1,0)*IF(D13='Оценка сложности задач'!$B$37,1,0)*'Оценка сложности задач'!$G$37)+(IF(C13='Оценка сложности задач'!$A$38,1,0)*IF(D13='Оценка сложности задач'!$B$38,1,0)*'Оценка сложности задач'!$G$38)+(IF(C13='Оценка сложности задач'!$A$39,1,0)*IF(D13='Оценка сложности задач'!$B$39,1,0)*'Оценка сложности задач'!$G$39)+(IF(C13='Оценка сложности задач'!$A$40,1,0)*IF(D13='Оценка сложности задач'!$B$40,1,0)*'Оценка сложности задач'!$G$40) -> 6
A14: 11 | B14: Логирование результата (журнал) и пометка письма | C14: Базы данных | D14: Легкая | E14: =(IF(C14='Оценка сложности задач'!$A$2,1,0)*IF(D14='Оценка сложности задач'!$B$2,1,0)*'Оценка сложности задач'!$G$2)+(IF(C14='Оценка сложности задач'!$A$3,1,0)*IF(D14='Оценка сложности задач'!$B$3,1,0)*'Оценка сложности задач'!$G$3)+(IF(C14='Оценка сложности задач'!$A$4,1,0)*IF(D14='Оценка сложности задач'!$B$4,1,0)*'Оценка сложности задач'!$G$4)+(IF(C14='Оценка сложности задач'!$A$5,1,0)*IF(D14='Оценка сложности задач'!$B$5,1,0)*'Оценка сложности задач'!$G$5)+(IF(C14='Оценка сложности задач'!$A$6,1,0)*IF(D14='Оценка сложности задач'!$B$6,1,0)*'Оценка сложности задач'!$G$6)+(IF(C14='Оценка сложности задач'!$A$7,1,0)*IF(D14='Оценка сложности задач'!$B$7,1,0)*'Оценка сложности задач'!$G$7)+(IF(C14='Оценка сложности задач'!$A$8,1,0)*IF(D14='Оценка сложности задач'!$B$8,1,0)*'Оценка сложности задач'!$G$8)+(IF(C14='Оценка сложности задач'!$A$10,1,0)*IF(D14='Оценка сложности задач'!$B$10,1,0)*'Оценка сложности задач'!$G$10)+(IF(C14='Оценка сложности задач'!$A$9,1,0)*IF(D14='Оценка сложности задач'!$B$9,1,0)*'Оценка сложности задач'!$G$9)+ (IF(C14='Оценка сложности задач'!$A$11,1,0)*IF(D14='Оценка сложности задач'!$B$11,1,0)*'Оценка сложности задач'!$G$11) + (IF(C14='Оценка сложности задач'!$A$12,1,0)*IF(D14='Оценка сложности задач'!$B$12,1,0)*'Оценка сложности задач'!$G$12) + (IF(C14='Оценка сложности задач'!$A$13,1,0)*IF(D14='Оценка сложности задач'!$B$13,1,0)*'Оценка сложности задач'!$G$13) + (IF(C14='Оценка сложности задач'!$A$14,1,0)*IF(D14='Оценка сложности задач'!$B$14,1,0)*'Оценка сложности задач'!$G$14) + (IF(C14='Оценка сложности задач'!$A$15,1,0)*IF(D14='Оценка сложности задач'!$B$15,1,0)*'Оценка сложности задач'!$G$15) + (IF(C14='Оценка сложности задач'!$A$16,1,0)*IF(D14='Оценка сложности задач'!$B$16,1,0)*'Оценка сложности задач'!$G$16) + (IF(C14='Оценка сложности задач'!$A$17,1,0)*IF(D14='Оценка сложности задач'!$B$17,1,0)*'Оценка сложности задач'!$G$17) + (IF(C14='Оценка сложности задач'!$A$18,1,0)*IF(D14='Оценка сложности задач'!$B$18,1,0)*'Оценка сложности задач'!$G$18) + (IF(C14='Оценка сложности задач'!$A$19,1,0)*IF(D14='Оценка сложности задач'!$B$19,1,0)*'Оценка сложности задач'!$G$19)+(IF(C14='Оценка сложности задач'!$A$20,1,0)*IF(D14='Оценка сложности задач'!$B$20,1,0)*'Оценка сложности задач'!$G$20)+(IF(C14='Оценка сложности задач'!$A$21,1,0)*IF(D14='Оценка сложности задач'!$B$21,1,0)*'Оценка сложности задач'!$G$21)+(IF(C14='Оценка сложности задач'!$A$22,1,0)*IF(D14='Оценка сложности задач'!$B$22,1,0)*'Оценка сложности задач'!$G$22)+(IF(C14='Оценка сложности задач'!$A$23,1,0)*IF(D14='Оценка сложности задач'!$B$23,1,0)*'Оценка сложности задач'!$G$23)+(IF(C14='Оценка сложности задач'!$A$24,1,0)*IF(D14='Оценка сложности задач'!$B$24,1,0)*'Оценка сложности задач'!$G$24)+(IF(C14='Оценка сложности задач'!$A$25,1,0)*IF(D14='Оценка сложности задач'!$B$25,1,0)*'Оценка сложности задач'!$G$25)+(IF(C14='Оценка сложности задач'!$A$26,1,0)*IF(D14='Оценка сложности задач'!$B$26,1,0)*'Оценка сложности задач'!$G$26)+(IF(C14='Оценка сложности задач'!$A$27,1,0)*IF(D14='Оценка сложности задач'!$B$27,1,0)*'Оценка сложности задач'!$G$27)+(IF(C14='Оценка сложности задач'!$A$28,1,0)*IF(D14='Оценка сложности задач'!$B$28,1,0)*'Оценка сложности задач'!$G$28)+(IF(C14='Оценка сложности задач'!$A$29,1,0)*IF(D14='Оценка сложности задач'!$B$29,1,0)*'Оценка сложности задач'!$G$29)+(IF(C14='Оценка сложности задач'!$A$30,1,0)*IF(D14='Оценка сложности задач'!$B$30,1,0)*'Оценка сложности задач'!$G$30)+(IF(C14='Оценка сложности задач'!$A$31,1,0)*IF(D14='Оценка сложности задач'!$B$31,1,0)*'Оценка сложности задач'!$G$31)+(IF(C14='Оценка сложности задач'!$A$32,1,0)*IF(D14='Оценка сложности задач'!$B$32,1,0)*'Оценка сложности задач'!$G$32)+(IF(C14='Оценка сложности задач'!$A$33,1,0)*IF(D14='Оценка сложности задач'!$B$33,1,0)*'Оценка сложности задач'!$G$33)+(IF(C14='Оценка сложности задач'!$A$34,1,0)*IF(D14='Оценка сложности задач'!$B$34,1,0)*'Оценка сложности задач'!$G$34)+(IF(C14='Оценка сложности задач'!$A$35,1,0)*IF(D14='Оценка сложности задач'!$B$35,1,0)*'Оценка сложности задач'!$G$35)+(IF(C14='Оценка сложности задач'!$A$36,1,0)*IF(D14='Оценка сложности задач'!$B$36,1,0)*'Оценка сложности задач'!$G$36)+(IF(C14='Оценка сложности задач'!$A$37,1,0)*IF(D14='Оценка сложности задач'!$B$37,1,0)*'Оценка сложности задач'!$G$37)+(IF(C14='Оценка сложности задач'!$A$38,1,0)*IF(D14='Оценка сложности задач'!$B$38,1,0)*'Оценка сложности задач'!$G$38)+(IF(C14='Оценка сложности задач'!$A$39,1,0)*IF(D14='Оценка сложности задач'!$B$39,1,0)*'Оценка сложности задач'!$G$39)+(IF(C14='Оценка сложности задач'!$A$40,1,0)*IF(D14='Оценка сложности задач'!$B$40,1,0)*'Оценка сложности задач'!$G$40) -> 22
A15: 12 | B15: Обработка ошибок и повторные попытки (ретраи/очередь) | C15: Настройка процесса | D15: Средняя | E15: =(IF(C15='Оценка сложности задач'!$A$2,1,0)*IF(D15='Оценка сложности задач'!$B$2,1,0)*'Оценка сложности задач'!$G$2)+(IF(C15='Оценка сложности задач'!$A$3,1,0)*IF(D15='Оценка сложности задач'!$B$3,1,0)*'Оценка сложности задач'!$G$3)+(IF(C15='Оценка сложности задач'!$A$4,1,0)*IF(D15='Оценка сложности задач'!$B$4,1,0)*'Оценка сложности задач'!$G$4)+(IF(C15='Оценка сложности задач'!$A$5,1,0)*IF(D15='Оценка сложности задач'!$B$5,1,0)*'Оценка сложности задач'!$G$5)+(IF(C15='Оценка сложности задач'!$A$6,1,0)*IF(D15='Оценка сложности задач'!$B$6,1,0)*'Оценка сложности задач'!$G$6)+(IF(C15='Оценка сложности задач'!$A$7,1,0)*IF(D15='Оценка сложности задач'!$B$7,1,0)*'Оценка сложности задач'!$G$7)+(IF(C15='Оценка сложности задач'!$A$8,1,0)*IF(D15='Оценка сложности задач'!$B$8,1,0)*'Оценка сложности задач'!$G$8)+(IF(C15='Оценка сложности задач'!$A$10,1,0)*IF(D15='Оценка сложности задач'!$B$10,1,0)*'Оценка сложности задач'!$G$10)+(IF(C15='Оценка сложности задач'!$A$9,1,0)*IF(D15='Оценка сложности задач'!$B$9,1,0)*'Оценка сложности задач'!$G$9)+ (IF(C15='Оценка сложности задач'!$A$11,1,0)*IF(D15='Оценка сложности задач'!$B$11,1,0)*'Оценка сложности задач'!$G$11) + (IF(C15='Оценка сложности задач'!$A$12,1,0)*IF(D15='Оценка сложности задач'!$B$12,1,0)*'Оценка сложности задач'!$G$12) + (IF(C15='Оценка сложности задач'!$A$13,1,0)*IF(D15='Оценка сложности задач'!$B$13,1,0)*'Оценка сложности задач'!$G$13) + (IF(C15='Оценка сложности задач'!$A$14,1,0)*IF(D15='Оценка сложности задач'!$B$14,1,0)*'Оценка сложности задач'!$G$14) + (IF(C15='Оценка сложности задач'!$A$15,1,0)*IF(D15='Оценка сложности задач'!$B$15,1,0)*'Оценка сложности задач'!$G$15) + (IF(C15='Оценка сложности задач'!$A$16,1,0)*IF(D15='Оценка сложности задач'!$B$16,1,0)*'Оценка сложности задач'!$G$16) + (IF(C15='Оценка сложности задач'!$A$17,1,0)*IF(D15='Оценка сложности задач'!$B$17,1,0)*'Оценка сложности задач'!$G$17) + (IF(C15='Оценка сложности задач'!$A$18,1,0)*IF(D15='Оценка сложности задач'!$B$18,1,0)*'Оценка сложности задач'!$G$18) + (IF(C15='Оценка сложности задач'!$A$19,1,0)*IF(D15='Оценка сложности задач'!$B$19,1,0)*'Оценка сложности задач'!$G$19)+(IF(C15='Оценка сложности задач'!$A$20,1,0)*IF(D15='Оценка сложности задач'!$B$20,1,0)*'Оценка сложности задач'!$G$20)+(IF(C15='Оценка сложности задач'!$A$21,1,0)*IF(D15='Оценка сложности задач'!$B$21,1,0)*'Оценка сложности задач'!$G$21)+(IF(C15='Оценка сложности задач'!$A$22,1,0)*IF(D15='Оценка сложности задач'!$B$22,1,0)*'Оценка сложности задач'!$G$22)+(IF(C15='Оценка сложности задач'!$A$23,1,0)*IF(D15='Оценка сложности задач'!$B$23,1,0)*'Оценка сложности задач'!$G$23)+(IF(C15='Оценка сложности задач'!$A$24,1,0)*IF(D15='Оценка сложности задач'!$B$24,1,0)*'Оценка сложности задач'!$G$24)+(IF(C15='Оценка сложности задач'!$A$25,1,0)*IF(D15='Оценка сложности задач'!$B$25,1,0)*'Оценка сложности задач'!$G$25)+(IF(C15='Оценка сложности задач'!$A$26,1,0)*IF(D15='Оценка сложности задач'!$B$26,1,0)*'Оценка сложности задач'!$G$26)+(IF(C15='Оценка сложности задач'!$A$27,1,0)*IF(D15='Оценка сложности задач'!$B$27,1,0)*'Оценка сложности задач'!$G$27)+(IF(C15='Оценка сложности задач'!$A$28,1,0)*IF(D15='Оценка сложности задач'!$B$28,1,0)*'Оценка сложности задач'!$G$28)+(IF(C15='Оценка сложности задач'!$A$29,1,0)*IF(D15='Оценка сложности задач'!$B$29,1,0)*'Оценка сложности задач'!$G$29)+(IF(C15='Оценка сложности задач'!$A$30,1,0)*IF(D15='Оценка сложности задач'!$B$30,1,0)*'Оценка сложности задач'!$G$30)+(IF(C15='Оценка сложности задач'!$A$31,1,0)*IF(D15='Оценка сложности задач'!$B$31,1,0)*'Оценка сложности задач'!$G$31)+(IF(C15='Оценка сложности задач'!$A$32,1,0)*IF(D15='Оценка сложности задач'!$B$32,1,0)*'Оценка сложности задач'!$G$32)+(IF(C15='Оценка сложности задач'!$A$33,1,0)*IF(D15='Оценка сложности задач'!$B$33,1,0)*'Оценка сложности задач'!$G$33)+(IF(C15='Оценка сложности задач'!$A$34,1,0)*IF(D15='Оценка сложности задач'!$B$34,1,0)*'Оценка сложности задач'!$G$34)+(IF(C15='Оценка сложности задач'!$A$35,1,0)*IF(D15='Оценка сложности задач'!$B$35,1,0)*'Оценка сложности задач'!$G$35)+(IF(C15='Оценка сложности задач'!$A$36,1,0)*IF(D15='Оценка сложности задач'!$B$36,1,0)*'Оценка сложности задач'!$G$36)+(IF(C15='Оценка сложности задач'!$A$37,1,0)*IF(D15='Оценка сложности задач'!$B$37,1,0)*'Оценка сложности задач'!$G$37)+(IF(C15='Оценка сложности задач'!$A$38,1,0)*IF(D15='Оценка сложности задач'!$B$38,1,0)*'Оценка сложности задач'!$G$38)+(IF(C15='Оценка сложности задач'!$A$39,1,0)*IF(D15='Оценка сложности задач'!$B$39,1,0)*'Оценка сложности задач'!$G$39)+(IF(C15='Оценка сложности задач'!$A$40,1,0)*IF(D15='Оценка сложности задач'!$B$40,1,0)*'Оценка сложности задач'!$G$40) -> 16
